Workbook
Name MY_FUNCTION1: LAMBDA(SUMPRODUCT(--(range="color")))

Sheet ID Location
A1: ID | B1: Cabinet Location | C1: Binder # | D1: IPAD
A2: DBS-0044 | B2: 1 | C2: 6 | D2: 2 ENGLISH
A3: DBS-0053 | B3: 1 | C3: 7 | D3: 1 SPANISH
A4: DBS-0219 | B4: 2 | C4: 11 | D4: 2 SPANISH
A5: DBS-0349 | B5: 2 | C5: 17 | D5: 1 SPANISH
A6: DBS-0008 | B6: 1 | C6: 3 | D6: 1 SPANISH
A7: DBS-0299 | B7: 2 | C7: 15 | D7: 1 SPANISH
A8: DBS-0360 | B8: 3 | C8: 28 | D8: 1 SPANISH
A9: DBS-0322 | B9: 1 | C9: 9 | D9: 1 SPANISH
A10: DBS-0382 | B10: 2 | C10: 18 | D10: 1 SPANISH
A11: DBS-0432 | B11: 5 | C11: 47 | D11: 1 ENGLISH
A12: DBS-0221 | B12: 3 | C12: 19 | D12: 1 SPANISH
A13: DBS-0404 | B13: 3 | C13: 28 | D13: 2 SPANISH
... A28: DBS-0169 | B28: 3 | C28: 19 | D28: 2 SPANISH
A29: DBS-0108 | B29: 2 | C29: 13
A30: DBS-0450 | B30: 3 | C30: 24 | D30: 1 SPANISH
A31: DBS-0379 | B31: 3 | C31: 25 | D31: 2 SPANISH
A32: DBS-0414 | B32: 3 | C32: 25 | D32: 1 SPANISH
A33: DBS-0055 | B33: 5 | C33: 47 | D33: 1 SPANISH
A34: DBS-0586 | B34: 3 | C34: 27 | D34: 1 SPANISH
A35: DBS-0569 | B35: 6 | C35: 55 | D35: 1 SPANISH
A36: DBS-0028 | B36: 1 | C36: 2 | D36: 1 SPANISH (2024) and 2 SPANISH (2024,2025)
A37: DBS-0268 | B37: 2 | C37: 15
A38: DBS-0429 | B38: 3 | C38: 22 | D38: 1 SPANISH
A39: DBS-0499 | B39: 2 | C39: 14 | D39: 1 SPANISH
A40: DBS-0658 | B40: 4 | C40: 31 | D40: 2 SPANISH
A41: DBS-0498 | B41: 3 | C41: 20 | D41: 2 SPANISH
A42: DBS-0216 | B42: 3 | C42: 22 | D42: 2 SPANISH
A43: DBS-0418 | B43: 2 | C43: 12 | D43: 2 SPANISH
A44: DBS-0620 | B44: 4 | C44: 29 | D44: 2 SPANISH
A45: DBS-0502 | B45: 2 | C45: 10 | D45: 2 SPANISH
A46: DBS-0199 | B46: 2 | C46: 14 | D46: 2 ENGLISH
A47: DBS-0745 | B47: 6 | C47: 57 | D47: 2 ENGLISH
A48: DBS-0657 | B48: 4 | C48: 29 | D48: 1 SPANISH
A49: DBS-0884 | B49: 6 | C49: 50 | D49: 2 SPANISH | E49: 562-250-6793 new number starting June. Cell ending in 7879 will no longer be in service after may
A50: DBS-0542 | B50: 4 | C50: 36
A51: DBS-0705 | B51: 6 | C51: 57
A52: DBS-0597 | B52: 3 | C52: 20 | D52: 2 SPANISH
A53: DBS-0800 | B53: 5 | C53: 39 | D53: 2 SPANISH
A54: DBS-0741 | B54: 6 | C54: 56 | D54: 2 SPANISH
...

Sheet Completed Visits
A1: SECOND YEAR | G1: THIRD YEAR | H1: last verified 10/14 | I1: important to stick to 2yr mri protocol | K1: FOURTH YEAR | L1: last verified: 10/14 | M1: important to document np date for a 1yr gap | O1: COMPLETED
A2: ID | B2: Participant Assigned to | C2: Scheduling Month | D2: Notes | E2: Diabetes Status | G2: ID | H2: Scheduling Month | I2: Notes | K2: ID | L2: Scheduling Month | M2: Notes | O2: ID | P2: Month/ Year | Q2: Notes
A3: DBS-0007 | B3: GT | C3: 45413 | E3: D | G3: DBS-0382 | H3: 45778 | K3: DBS-0044 | L3: 46143 | O3: DBS-0007 | P3: 46143
A4: DBS-0008 | B4: LC | C4: 45413 | D4: LP pending | E4: D | G4: DBS-0322 | H4: 45778 | K4: DBS-0322 | L4: 46143 | O4: DBS-0044 | P4: 46143
A5: DBS-0028 | B5: GT | C5: 45413 | D5: LP Pending | E5: D | G5: DBS-0183 | H5: 45778 | K5: DBS-0007 | L5: 46143 | O5: DBS-0322 | P5: 46143
A6: DBS-0044 | B6: LC | C6: 45413 | E6: D | G6: DBS-0180 | H6: 45778 | K6: DBS-0053 | L6: 46143 | O6: DBS-0073 | P6: 46143
A7: DBS-0053 | B7: LC | C7: 45413 | E7: D | G7: DBS-0053 | H7: 45778 | K7: DBS-0169 | L7: 46143 | O7: DBS-0169 | P7: 46143
A8: DBS-0139 | B8: GT | C8: 45413 | E8: ND | G8: DBS-0044 | H8: 45778 | K8: DBS-0073 | L8: 46143 | O8: DBS-0360 | P8: 46174
A9: DBS-0180 | B9: LC | C9: 45413 | D9: LP Pending | E9: D | G9: DBS-0007 | H9: 45778 | K9: DBS-0360 | L9: 46174 | O9: DBS-0008 | P9: 46174
A10: DBS-0183 | B10: GT | C10: 45413 | E10: D | G10: DBS-0419 | H10: 45809 | K10: DBS-0054 | L10: 46174 | O10: DBS-0054 | P10: 46174
A11: DBS-0219 | B11: LC | C11: 45413 | E11: D | G11: DBS-0404 | H11: 45809 | K11: DBS-0154 | L11: 46174 | O11: DBS-0053 | P11: 46174
A12: DBS-0268 | B12: LC | C12: 45413 | E12: D | G12: DBS-0381 | H12: 45809 | K12: DBS-0221 | L12: 46174 | O12: DBS-0299 | P12: 46174
A13: DBS-0322 | B13: GT | C13: 45413 | E13: D | G13: DBS-0360 | H13: 45809 | K13: DBS-0008 | L13: 46174 | O13: DBS-0063 | P13: 46174
A14: DBS-0352 | B14: LC | C14: 45413 | E14: ND | G14: DBS-0352 | H14: 45809 | K14: DBS-0235 | L14: 46174 | O14: DBS-0235 | P14: 46174
A15: DBS-0382 | B15: LC | C15: 45413 | E15: ND | G15: DBS-0299 | H15: 45809 | K15: DBS-0299 | L15: 46174 | O15: DBS-0154 | P15: 46174
A16: DBS-0404 | B16: GT | C16: 45413 | E16: ND | G16: DBS-0235 | H16: 45809 | K16: DBS-0063 | L16: 46174 | O16: DBS-0221 | P16: 46174
A17: DBS-0013 | B17: GT | C17: 45444 | E17: D | G17: DBS-0221 | H17: 45809 | K17: DBS-0180 | L17: 46204 | O17: DBS-0180 | P17: 46204
A18: DBS-0054 | B18: GT | C18: 45444 | E18: D | G18: DBS-0169 | H18: 45809 | K18: DBS-0028 | L18: 46204 | O18: DBS-0349 | P18: 46204
A19: DBS-0063 | B19: LC | C19: 45444 | E19: D | G19: DBS-0154 | H19: 45809 | K19: DBS-0349 | L19: 46204 | O19: DBS-0430 | P19: 46204
A20: DBS-0073 | B20: LC | C20: 45444 | E20: D | G20: DBS-0139 | H20: 45809 | K20: DBS-0430 | L20: 46204 | O20: DBS-0586 | P20: 46204
A21: DBS-0108 | B21: LC | C21: 45444 | D21: LP Pending | E21: ND | G21: DBS-0073 | H21: 45809 | K21: DBS-0502 | L21: 46241 | O21: DBS-0432 | P21: 46235
A22: DBS-0154 | B22: LC | C22: 45444 | E22: D | G22: DBS-0063 | H22: 45809 | K22: DBS-0442 | L22: 46235 | O22: DBS-0499 | P22: 46235
A23: DBS-0169 | B23: LC | C23: 45444 | E23: D | G23: DBS-0054 | H23: 45809 | K23: DBS-0199 | L23: 46235 | O23: DBS-0429 | P23: 46235
A24: DBS-0221 | B24: GT | C24: 45444 | E24: ND | G24: DBS-0008 | H24: 45809 | K24: DBS-0429 | L24: 46235 | O24: DBS-0512 | P24: 46235
A25: DBS-0235 | B25: LC | C25: 45444 | E25: D | G25: DBS-0430 | H25: 45839 | K25: DBS-0381 | L25: 46235 | M25: *have him sign front page of DE4 consent | O25: DBS-0139 | P25: 46235
A26: DBS-0299 | B26: GT | C26: 45444 | E26: D | G26: DBS-0414 | H26: 45839 | K26: DBS-0450 | L26: 46235 | O26: DBS-0404 | P26: 46235
A27: DBS-0381 | B27: LC | C27: 45444 | E27: ND | G27: DBS-0379 | H27: 45839 | K27: DBS-0586 | L27: 46235 | O27: DBS-0381 | P27: 46235
A28: DBS-0419 | B28: LC | C28: 45444 | E28: ND | G28: DBS-0349 | H28: 45839 | K28: DBS-0499 | L28: 46235 | O28: DBS-0199 | P28: 46235
A29: DBS-0360 | B29: GT | C29: 45445 | E29: ND | G29: DBS-0028 | H29: 45839 | K29: DBS-0139 | L29: 46235 | O29: DBS-0502 | P29: 46235
A30: DBS-0055 | B30: GT | C30: 45474 | D30: LP Pending | E30: ND | G30: DBS-0586 | H30: 45870 | K30: DBS-0404 | L30: 46235 | O30: DBS-0450 | P30: 46235
A31: DBS-0349 | B31: LC | C31: 45474 | E31: D | G31: DBS-0512 | H31: 45870 | K31: DBS-0512 | L31: 46235 | O31: DBS-0772 | P31: 46266
A32: DBS-0379 | B32: GT | C32: 45474 | E32: ND | G32: DBS-0502 | H32: 45870 | K32: DBS-0432* | L32: 46235 | O32: DBS-0676 | P32: 46266
A33: DBS-0414 | B33: GT | C33: 45474 | E33: ND | G33: DBS-0499 | H33: 45870 | K33: DBS-0676 | L33: 46266 | O33: DBS-0613 | P33: 46296
A34: DBS-0430 | B34: LC | C34: 45474 | D34: LP Pending | E34: D | G34: DBS-0450 | H34: 45870 | K34: DBS-0772 | L34: 46266 | O34: DBS-0830 | P34: 46296
A35: DBS-0432* | B35: GT | C35: 45474 | D35: LP pending | E35: D | G35: DBS-0442 | H35: 45870 | K35: DBS-0830 | L35: 46266 | M35: skipped a year- never came in for 2nd year | O35: DBS-0569 | P35: 46296
A36: DBS-0199 | B36: GT | C36: 45505 | E36: D | G36: DBS-0432* | H36: 45870 | K36: DBS-0613 | L36: 46296 | O36: DBS-0055 | P36: 46296
A37: DBS-0418 | B37: LC | C37: 45505 | D37: LP Pending | E37: D | G37: DBS-0429 | H37: 45870 | K37: DBS-0620 | L37: 46296
A38: DBS-0429 | B38: GT | C38: 45505 | E38: D | G38: DBS-0199 | H38: 45870 | K38: DBS-0055 | L38: 46296
A39: DBS-0450 | B39: GT | C39: 45505 | E39: D | G39: DBS-0013 | H39: 45870 | K39: DBS-0569 | L39: 46296
A40: DBS-0499 | B40: LC | C40: 45505 | D40: LP Pending | E40: D | G40: DBS-0676 | H40: 45901 | K40: DBS-0745 | L40: 46296
...

Sheet MRI Dates Available
A1: Month | B1: MRI Dates | C1: MRI Times | J1: SCAN COST | K1: 720
A2: May '25 | B2: 45793 | C2: Scan: 8am-9am | D2: Cancelled. Kat out of office. | G2: scheduled/ taken
B3: 45793 | C3: Scan: 11am-12pm | D3: Ghost date. Slot not filled. | G3: pending
B4: 45796 | C4: Scan: 11am-12pm | G4: cancelled
B5: 45796 | C5: Scan: 8am-9am | G5: came in but did not comnplete scan - rescheduled
B6: 45798 | C6: Scan: 8am-9am | D6: Ghost date. Slot not filled.
B7: 45799 | C7: Scan: 8am-9am
B8: 45804 | C8: Scan: 8am-9am | D8: Cancelled. Not filled.
A9: June '25 | B9: 45810 | C9: Scan: 8am-9am | D9: Cancelled. Participant drop out.
B10: 45810 | C10: Scan: 10am-11am | D10: Participant rescheduled.
B11: 45811 | C11: Scan: 8am-9am
B12: 45812 | C12: Scan: 9:30am-10:30am
B13: 45813 | C13: Scan: 8am-9am
B14: 45814 | C14: Scan: 8am-9am
B15: 45814 | C15: Scan: 9:30am-10:30am
B16: 45817 | C16: Scan: 8am-9am | D16: Cancelled ahead of time. Not filled.
B17: 45817 | C17: Scan: 9:30am-10:30am
B18: 45818 | C18: Scan: 8am-9am
B19: 45819 | C19: Scan: 8am-9am
B20: 45819 | C20: Scan: 9:30am-10:30am | D20: July
B21: 45821 | C21: Scan: 8am-9am | D21: Cancelled ahead of time. Ghost date -not filled.
A22: July '25 | B22: 45847 | C22: Scan: 8am-9am | D22: June Participatn cancelled ahead of time.
B23: 45847 | C23: Scan: 9:30am-10:30am | D23: June Participatn cancelled ahead of time.
B24: 45848 | C24: Scan: 8am-9am | D24: May
B25: 45852 | C25: Scan: 8:30am-9:30am | D25: 0028 came in but did not start scan - rescheduled for 7/21/26
B26: 45859 | C26: Scan: 10:30am-11:30am
B27: 45861 | C27: Scan: 8:00am-9:00am | D27: June
B28: 45866 | C28: Scan: 8:30am-9:30am | D28: May Participatn cancelled ahead of time.
B29: 45866 | C29: Scan: 8:30am-9:30am | D29: August
B30: 45868 | C30: Scan: 9:00am-10:00am | D30: August
A31: August '25 | B31: 45870 | C31: Scan: 9:00am-10:00am
B32: 45873 | C32: Scan: 10am-11am | D32: June pt - 0169 came in but did not start scan.
B33: 45873 | C33: Scan: 11:30am-12:30pm | D33: June pt - 0073 came in but did not start scan.
B34: 45877 | C34: Scan:8:00am-9:00am
B35: 45880 | C35: Scan:8:00am-9:00am
B36: 45880 | C36: Scan: 9:30am-10:30am | D36: July
B37: 45882 | C37: Scan: 9:00am-10:00am scan rescheduled bc kat out
B38: 45882 | C38: Scan: 10:30am-11:30am scan rescheduled bc kat out
B39: 45889 | C39: Scan:8:00am-9:00am
B40: 45889 | C40: Scan: 9:30am-10:30am
...

Sheet 3rd Yr Scheduling Notes 
D1: MRI + BD Visits | I1: NP + CV Visits | M1: Old Scheduling Notes
A2: Month | B2: ID | D2: MRI/BD Scheduling Notes | E2: MRI Date | F2: BD Date | G2: MRI Scan Time | I2: NP/CV Scheduling Notes | J2: NP Date | K2: CV Date | M2: MRI Scheduling Notes | N2: BD Notes | O2: CV Scheduling Notes | Q2: Completed
A3: May | B3: DBS-0382 | D3: DROPPED JULY 2025 ;; Responded to email. He is in mex and does not anticipate returning till 3-4 yrs from now. No longer able to participate. 7/23/25 JE ;; No answer. 7/14/25 JE ;; LC 04/03: Out of country. F/u in 3 months | M3: Left vm and sent email 7/23/25 JE ;; Left vm and sent text. 7/14/25 JE ;; Was able to leave vm. 7/3/25 JE ;; Operator message, "subscriber not in service." Will try again 6/2/25 JE ;; LC 04/03: Out of country. F/u in 3 months
A4: May | B4: DBS-0322 | E4: 45796 | F4: 45796 | G4: Scan: 8am-9am | I4: Would like to combine visits if possible. Schedule a bit complicated but she is flexible. -JE 4/16/25 | J4: 45792 | K4: 45792 | N4: BD needed to be moved to MRI date bc labs need to be reordered. 5/15/25 -JE ;; IV 5/2: needs uber LC 04/03: Call back tomorrow
A5: May | B5: DBS-0053 | E5: 45930 | F5: 45778 | G5: Scan: 8am-9am | J5: 45778 | K5: 45778 | M5: Participant is back. Apt is pending atm. CIA showing as insufficent funding att. but dbs grant was approved. Will follow up. 9/4/25 JE ;; Let me know that she had to go out of country for an emergency and that she will reach back out when she is back to rescheduled. Cancelled scan for 7/28/25 on 7/23/25 JE ;; Asked to reschedule again bc she broke a toe and cant walk. Was scheduled for June 9th at 8 am. New date for July. 5/30/25 JE ;; Asked to change originally set date of may 27th to june 9th instead. 5/2/25 -JE ;; Left vm and sent text 4/17/25 -JE ;; LC 04/03: Schedule MRI for end of month
A6: May | B6: DBS-0044 | E6: 45796 | F6: 45790 | G6: Scan: 11am-12pm | J6: 45790 | K6: 45796 | N6: LC 04/03: Left vm | O6: IV 5/13: moved to mri day bc it was missed
A7: May | B7: DBS-0183 | D7: DROPPED MAY 2025 ;; Letter mailed out. All forms of contact exhausted. No answer 5/15/25 JE | M7: Left vm and sent text. 7/3/35 JE ;; Mailed out letter. 5/15/25 -JE ;; No answer. 5/6/25 -JE ;; Left vm and sent email.5/1/25 -JE ;; Left vm. 4/24/25 -JE ;; No answer. Sent text.4/16/25 -JE | N7: IV 5/2: left vm, sent text LC 04/03: Left vm
A8: May | B8: DBS-0180 | E8: 45848 | F8: 45810 | G8: Scan: 8am-9am | J8: 45810 | K8: 45819 | M8: Able to schedule over the phone during his NP visit 6/2/25 -JE ;; MJ 05/22:Would like to reschedule for a wk after CV on 06/11/25 ;; Called to reschedule bc Kat will be out Fri (5/16/25). No answer, left vm. New date TBD. 5/14/25 -JE ;; No answer. Sent text. 4/16/25 -JE | N8: MJ 05/22: Uber needed MJ 05/21: Left VM + sent text & email IV 5/2: left vm, sent text LC 04/03: Left vm
A9: May | B9: DBS-0007 | E9: 45799 | F9: 45796 | G9: Scan: 8am-9am | J9: 45796 | K9: 45796 | Q9: 5
A10: June | B10: DBS-0419 | D10: DROPPED MAY 2025 ;; Lead messaged that she is moving to mexico and is no longer able to continue with study. Was supposed to come in on 06/08/25. 5/28/25 -JE | G10: Scan: 8am-9am | M10: Lead messaged that she is moving to mexico and is no longer able to continue with study. 5/28/25 -JE | N10: MJ 05/21: Uber needed
A11: June | B11: DBS-0404 | D11: Sent checkin message. 8/4/25 JE ;; Husband will reach out when ready. Check in in aug. 7/21/25 JE ;; Let IV know they need to cancel, needs reschedule... 7/8/25 JE ;; IV 7/1: rescheduled bd other day | E11: 45889 | F11: 45897 | G11: Scan: 9:30am-10:30am | I11: IV and JE tag teaming on MRI day. 8/4/25 JE ;; See MRI note. 7/8/25 JE ;; Husband wife duo. Would like to combine all visits if possible. -JE 4/28/25 | J11: 45889 | K11: 45897 | M11: Husband wife duo. Needs new date. Was originally scheduled for 7/9/25. Urgent matter had to be cancelled. MRI and NP and CV together 7/8/25 JE ;; Open conversation through text re schdeuleding for him and partner. 4/25/25 -JE ;; Sent text.4/24/25 -JE ;; Left vm 4/17/25 -JE | N11: Husband said he has a surgery and will reach back out when ready to reschedule. 7/21/25 JE ;; Will complete NP day of the MRI. Wife jusband duo. 6/30/25 JE ;; IV 6/17: couldnt make it, app for surgery end of july IV 6/12: will drive
A12: June | B12: DBS-0381 | D12: Can't do Tuesday or Friday. And needs morning appointments. 8/20/25 JE ;; IV 7/30: had to reschedule again , doctors visits 7/22/25 MRI got moved up to 7:30am and had to move NP to CV day bc he has a doc visit tomorrow. He mentioned that that he got an extension on PT. His apointments are Tue and Fri's. Confirmed that visit on the 31st still works ok. JE ;; IV 7/1: wanted to add np tp mri day and cv+bd other day Would like to schedule for July. Was in a car accident and has a neck brace at the moment. 6/2/25 -JE | E12: 45861 | F12: 45890 | G12: Scan: 8:00am-9:00am | I12: See schdeuling notes. JE ;; Same day as MRI | J12: 45890 | K12: 45890 | M12: Same day but time moved up. 7/22/25 JE ;; New date for July 23rd. 6/2/25 JE ;; Participant canceled needs to reschedule. Car accident w/ neck brace at the moment. 5/30/25 JE ;; Has surgery 28th of April. Still open to scheduling for June. 4/17/25 -JE | N12: IV 6/23: left vm sent text IV 5/29: left vm, sent text
A13: June | B13: DBS-0360 | E13: 45812 | F13: 45813 | G13: Scan: 9:30am-10:30am | J13: 45812 | K13: 45812 | N13: IV 5/29: Np, cv same as mri day, bd other day will drive
A14: June | B14: DBS-0352 | D14: DROPPED JAN 2026 ;; No answer to calls or text 1/29/26 ;; No answer. Sent text. 1/27/26 JE ;; Checking in. No answer. Left vm. 12/2/25 JE ;; IV 5/29: had an accident, asked to be removed bc she has alot of physical therapy andrecovery process, maybe contact in a few months | I14: Would like to combine all visits if possible. -JE 4/17/25 | M14: Had an accident but should be better by June. 4/17/25 -JE
A15: June | B15: DBS-0299 | E15: 45818 | F15: 45820 | G15: Scan: 8am-9am | J15: 45820 | K15: 45820 | N15: IV 5/29: will drive
A16: June | B16: DBS-0235 | D16: Tuesdays or Friday (days off) | E16: 45814 | F16: 45825 | G16: Scan: 9:30am-10:30am | J16: 45825 | K16: 45825 | M16: Open conversation through text re scheduling. 4/25/25 -JE ;; Sent text. 4/24/25 -JE ;; Left vm 4/17/25 -JE | N16: IV 5/29: will call me back today
A17: June | B17: DBS-0221 | E17: 45819 | F17: 45818 | G17: Scan: 8am-9am | J17: 45818 | K17: 45818 | M17: Date confirmed. 4/23/25 -JE ;; Lead called back. Confirmation pending for 6/11 @7:30 am. Would drive. 4/21/25 -JE ;; Left vm 4/17/25 -JE | N17: IV 5/29: will drive
A18: June | B18: DBS-0169 | E18: 45994 | F18: 45807 | G18: Scan: 8am-9am | J18: 45807 | K18: 45807 | M18: Needs to reschedule. Moved from oct 28 to first week of dec. 10/6/25 JE ;; Tentative apt. set 9/17/25 JE ;; MRI TBD due to funding. Husband was notified and will let wife know. Reschedule as soon as able to book scans again. 9/2/25 JE ;; Ventura couple. Was scheduled for 8/4/25 and came in but had breakfast so could not scan. New date for Sept 8th. 8/4/25 pending (funding not available att). Follow up on cia. JE ;; Scheduled for Aug. -JE 4/24/25 ;; Left vm -JE 4/17/25 | N18: IV 5/22: will drive, with wife Couple from Ventura. Will be out of country June-July. -JE 4/24/25
A19: June | B19: DBS-0154 | E19: 45813 | F19: 45819 | G19: Scan: 8am-9am | J19: 45819 | K19: 45819 | N19: IV 5/29: will drive
A20: June | B20: DBS-0139 | E20: 45889 | F20: 45897 | G20: Scan: 8am-9am | I20: IV and JE tag teaming on MRI day. 8/4/25 JE ;; See MRI note on DBS-0404. 7/8/25 JE ;; Husband wife duo. Would like to combine all visits if possible. -JE 4/28/25 | J20: 45889 | K20: 45897 | M20: Wife and husband coming together. 4/28/25 - JE ;; Sent text. 4/24/25 -JE ;; Left vm 4/17/25 -JE | N20: Husband said he has a surgery and will reach back out when ready to reschedule. 7/21/25 JE ;; Will complete NP day of the MRI. Wife jusband duo. 6/30/25 JE ;; IV 6/17: couldnt make it, app for surgery end of july IV 6/12: will drive
A21: June | B21: DBS-0073 | E21: 45994 | F21: 45807 | G21: Scan: 9:30am-10:30pm | J21: 45807 | K21: 45807 | M21: Needs to reschedule. Moved from oct 28 to first week of dec. 10/6/25 JE ;; Tentative apt. set 9/17/25 JE ;; Left message with husband 9/2/25 JE ;; Ventura couple. Was scheduled for 8/4/25 and came in but had breakfast so could not scan. New date for Sept 8th. 8/4/25 JE ;; Scheduled for Aug. 4/24/25 -JE ;; Left vm 4/17/25 -JE | N21: IV 5/22: will drive, with husband Couple from Ventura. Will be out of country June-July. -JE 4/24/25
A22: June | B22: DBS-0063 | E22: 45814 | F22: 45833 | G22: Scan: 8am-9am | I22: Fridays preferred. Open to combining visits if possible. -JE 4/17/25 | J22: 45833 | K22: 45833 | N22: IV 5/22: will drive, or might need uber
A23: June | B23: DBS-0054 | E23: 45811 | F23: 45813 | G23: Scan: 8am-9am | I23: Would like to combine visits if possible. -JE 4/17/25 | J23: 45813 | K23: 45813 | N23: IV 5/22: needs uber
A24: June | B24: DBS-0008 | E24: 45817 | F24: 45824 | G24: Scan: 9:30am-10:30am | J24: 45824 | K24: 45824 | M24: Will need new clincard 4/24/25 -JE ;; Left vm 4/17/25 -JE | N24: IV 5/22: needs uber | Q24: 13
A25: July | B25: DBS-0430 | E25: 45880 | F25: 45848 | G25: Scan: 9:30am-10:30am | I25: IV 6/23: bd+np, will drive | J25: 45848 | K25: 45880 | M25: Cheking Aug dates with Kat. Green light to book back to back. New date 8/11/25. 7/14/25 JE ;; Needs new date. Waiting on call back from second MRI visit that week to possible swap dates. Otherwise will be schedueld for Aug. Was scheduled for 7/21/25. 7/11/25 -JE ;; | N25: IV 6/23: bd+np, will drive | O25: New date. Was scheduled for 7/21/25. 7/11/25 -JE ;; IV 6/23: mri+ cv, will drive
A26: July | B26: DBS-0414 | D26: DROPPED NOV 2025 ;; Waiting for reply - sent follow up group text 11/19/25 JE ;; Said she needs to talk to her sis and then will call back. 11/12/25 JE ;; Asked for more time before scheduling anything. Check back next month. 10/3/25 JE ;; Follow up in October. 0414 expressed that 0379 shared she may not want to cont. bc they have fam problems att. BUT opened to beinging contacted again in a few months... 8/4/25 JE ;; Contact 0379 to schedule they want visits to be together. 0414 is ok with any day 0379 is able to do. | M26: Shared that due to family matters no longer able to continue. And her sis either. 11/21/25 JE ;; No answer. Called back and said she might still be interested but her sis no. Will call back. 11/19/25 JE ;; Said she will call back. 11/12/25 JE ;; Asked for more time before scheduling anything. Check back next month. 10/3/25 JE ;; Asked to set up schedule with 0379 (related) to be the same day. 5/22/25 -JE
A27: July | B27: DBS-0379 | D27: DROPPED NOV 2025 ;; Waiting for reply - sent follow up group text 11/19/25 JE ;; Follow up in October. 0414 expressed that 0379 shared she may not want to cont. bc they have fam problems att. BUT opened to beinging contacted again in a few months... 8/4/25 JE ;; MJ 07/30:Will talk to sister,,texted MRI dates available Takes care of kids and will bedifficult to schedule long visits in July. Schedule for late August. Visit will be w/ sister. day 1 - MRI, NP / day 2- CV, BD 5/22/25 -JE | M27: Never answered but sis shared she will likely not cont. 11/21/25 JE ;; No answer. 11/19/25 JE ;; Left vm. 10/3/25 JE ;; Has not set up date. Left vm. 7/23/25 JE ;; Days offered are august 25, 27, 29. Asked to give her a call back. Needs to check her dates 7/3/25 JE ;; Not able to scheduel till IRB renewal is cleared. 5/22/25 -JE
A28: July | B28: DBS-0349 | D28: MJ 06/25: Driving | E28: 45819 | F28: 45853 | G28: Scan: 9:30am-10:30am | J28: 45853 | K28: 45853 | M28: No vmb. Sent text. Open conversation through text. 6/2/25 JE ;; No vmb. Will try again. 5/22/25 -JE | N28: MJ 06/25: call failed,,sent text IV 6/24: call cannot go thru
A29: July | B29: DBS-0028 | D29: MJ 06/25: May need an Uber | E29: 45859 | F29: 45845 | G29: Scan: 10:30am-11:30am | J29: 45845 | K29: 45845 | M29: New MRI date 7/21/25. Does not need to draw blood. 7/16/25 JE ;; Came in for MRI on 7/14/25 but was not able to complete scan due to feeling dizzy (blood sugar may have been low). Would like to reschedule. New date TBD. 7/14/25 JE | Q29: 3
A30: August | B30: DBS-0586 | D30: MJ 07/22: Left VM + sent text 6/25 NC Mailed Letter ;; Was on vacation but is back now and ready to schedule. JE | E30: 45891 | F30: 45882 | G30: Scan: 10:00am-11:00am | J30: 45875 | K30: 45882 | M30: Blocked out by kat for us to schedule once IRB clears. 7/3/35 JE;; Left vm and sent text. 6/24/25 JE ;; Left vm. 6/5/25 JE | N30: MJ 07/22: Uber needed
A31: August | B31: DBS-0512 | D31: IV 07/1: wanted to add cv mri day, bd+np other date Prefers Tuesdays if possible. Advance notice opens availability. JE | E31: 45868 | F31: 45897 | G31: Scan: 9:00am-10:00am | J31: 45897 | K31: 45868 | M31: Left vm. 6/5/25 JE | N31: Needs new date. Will get his schedule for September Aug 30th. New date TBD BD and NP combined. 8/14/25 JE ;; MJ 07/31: Rescheduled visit for 08/18
A32: August | B32: DBS-0502 | D32: Open to schedule. excpt will be going out of the country Aug 22 (or sooner) for about two weeks. JE | E32: 45866 | F32: 45876 | G32: Scan: 8:00am-9:00am | J32: 45876 | K32: 45876 | M32: Participant moved. Originally scheduled for 8/7. New date 7/28. 7/23/25 JE
A33: August | B33: DBS-0499 | D33: Some pain walking. Needs to move slowly. Had shoulder surgery. In rehab but should be better by August. Ok to schedule. Not working att. Open. JE | E33: 45894 | F33: 45876 | G33: Scan: 08:30am-10:30am | J33: 45876 | K33: 45876 | M33: Originally scheduled for 8/13/25 but changed to 8/25/25 due to kat being out. 7/23/25 JE ;; Left vm. 6/5/25 JE | N33: Originally schedued for aug 4 but has an appointment she forgot about. Will come in on the 7 instead. 7/31/25 JE
A34: August | B34: DBS-0450 | E34: 45891 | F34: 45883 | G34: Scan: 08:30am-10:30am | J34: 45883 | K34: 45883 | M34: Originally scheduled for 8/13/25 but changed to 8/22/25 due to kat being out. 7/23/25 JE
A35: August | B35: DBS-0442 | E35: 45870 | F35: 45884 | G35: Scan: 9:00am-10:00am | J35: 45884 | K35: 45884
A36: August | B36: DBS-0432* | D36: 6/25 NC Mailed Letter ;; Busy with church. But flexible-ish.... JE | E36: 45953 | F36: 45875 | G36: Scan: 8am-9am | J36: 45875 | K36: 45875 | M36: Kat out sick. New date needed. Funding pending... TBD... 8/20/25 JE ;; Blocked out by kat for us to schedule once IRB clears. 7/3/35 JE ;; Left vm and sent text. 6/24/25 JE ;; Left vm. 6/5/25 JE
A37: August | B37: DBS-0429 | D37: MJ 07/24: Would like a call back tomorrow to schedule | E37: 45880 | F37: 45887 | G37: Scan:8:00am-9:00am | J37: 45887 | K37: 45887
A38: August | B38: DBS-0199 | D38: Pref Friday , but open | E38: 45877 | F38: 45884 | G38: Scan:8:00am-9:00am | J38: 45884 | K38: 45884 | M38: Left vm. 6/5/25 JE
A39: August | B39: DBS-0013 | D39: DROPPED DEC 2025 ;; Lost contact. All forms of contact exhausted. No reply. 12/3/25 ;; DV 09/18: Mailed letter ;; Scheduled for 9/10/25 but has not been answering. Left vm, text and email. 9/8/25 JE ;; MJ 07/28: Left VM MJ 07/24: Left VM + sent text Would like to combine visits if possible. Needs to ask for permision at work. But flexible. | M39: Did not answer or show for MRI. Waiting to hear back. Called, sent text, and email. 8/27/25 JE ;; Originally scheduled for 8/6/25 but asked to reschedule. New date 8/27/25. JE 8/4/25 ;; | N39: MJ 09/18: St to vm,,left vm | Q39: 9
A40: September | B40: DBS-0676 | D40: IV 09/3: will drive MJ 09/02: left vm IV 8/28: left vm, sent text | E40: 45951 | F40: 45925 | G40: Scan:8:00am-9:00am | J40: 45925 | K40: 45925 | M40: Tentative apt. set 9/19/25 JE ;; Open conversation through text. 7/23/25 JE ;; Left vm 7/22/25 JE
...

Sheet 4th Yr Scheduling Notes
D1: NP + CV + BD Visits | J1: Thank you cards prepped up to 8/21/26 : NC
A2: Month | B2: ID | D2: NP/CV Scheduling Notes | E2: NP Date | F2: CV Date | G2: BD Date | I2: Thank you Card?
A3: 46143 | B3: DBS-0044 | C3: MJ | D3: MJ 04/06: Left VM + sent text | E3: 46154 | F3: 46154 | G3: 46154 | H3: IV 4/1: sent
A4: 46143 | B4: DBS-0322 | C4: MJ | D4: MJ 05/04: New dates pending,,pt had to reschedule MJ 04/15: uber needed, new address on red cap MJ 04/06: Left VM + sent text | E4: 46160 | F4: 46160 | G4: 46160
A5: 46143 | B5: DBS-0007 | C5: IV | D5: IV 5/4: needs uber, pending confirmation with dr. h | E5: 46150 | F5: 46150 | G5: 46150
A6: 46143 | B6: DBS-0053 | C6: JE | D6: Returns from mex tomorrow. Set for all visits in one day. 5/19/26 JE ;; Left vm. 5/13/26 JE ;; Out of the country. Requested call back in about two weeks. 4/23/26 JE | E6: 46181 | F6: 46181 | G6: 46181 | I6: TRUE
A7: 46143 | B7: DBS-0169 | C7: IV | D7: husband - Scheduled with his wife. Coming in same day/time. 4/23/26 JE | E7: 46169 | F7: 46169 | G7: 46169 | I7: TRUE
A8: 46143 | B8: DBS-0073 | C8: JE | D8: wife - Coming in with husband same day/time. 4/23/26 JE | E8: 46169 | F8: 46169 | G8: 46169 | I8: TRUE
A9: 46174 | B9: DBS-0360 | C9: MJ | D9: MJ 05/05:Driving | E9: 46174 | F9: 46174 | G9: 46174 | H9: MJ 5/5:Sent | I9: TRUE
A10: 46174 | B10: DBS-0054 | C10: MJ | D10: MJ 05/05: Uber needed | E10: 46177 | F10: 46177 | G10: 46177 | I10: TRUE
A11: 46174 | B11: DBS-0154 | C11: MJ | D11: Dr.H cancelled CV. Pt notified and offered full reschedule or to return for CV another day. She would like to keep BD and NP and schedule a new date for CV. Let her know that MJ will be in touch. 6/12/26 JE ;; MJ 05/05: Left vm + sent text | E11: 46189 | F11: 46202 | G11: 46189 | I11: TRUE
A12: 46174 | B12: DBS-0221 | C12: MJ | D12: MJ 05/11: Driving MJ 05/05: Left vm + sent text | E12: 46196 | F12: 46196 | G12: 46196
A13: 46174 | B13: DBS-0008 | C13: JE | D13: Will need Uber. 4/29/26 JE ;; Left vm. 4/23/26 JE | E13: 46176 | F13: 46176 | G13: 46176 | I13: TRUE
A14: 46174 | B14: DBS-0235 | C14: JE | D14: Reminder text sent. Participant cancelled - asked for Saturdays. Let him know only mon-fri. Only other day he can come in is next week the 11th. 5/29/26 JE ;; Coming from th OC. 4/23/26 JE | E14: 46184 | F14: 46184 | G14: 46184 | I14: TRUE
A15: 46174 | B15: DBS-0299 | C15: JE | D15: Will drive. 4/23/26 JE | E15: 46182 | F15: 46182 | G15: 46182 | I15: TRUE
A16: 46174 | B16: DBS-0063 | C16: JE | D16: Left vm. 4/23/26 JE | E16: 46183 | F16: 46183 | G16: 46183 | I16: TRUE
A17: 46204 | B17: DBS-0180 | C17: MJ | D17: MJ 07/08: Pt had to reschedule his BD & CV MJ 06/22:uber needed, doing NP one day and then CV/BD the followng wk MJ 06/02: Left VM + sent text | E17: 46210 | F17: 46231 | G17: 46231 | H17: MJ 6/2: Sent | I17: TRUE
A18: 46204 | B18: DBS-0028 | C18: MJ | D18: IV 9/16: sent follow up , left vm IV 9/9: sent follow up to confirm lunes as early as possible... 8:30am?... Tentative date set up - I let him know I would confirm w/ MJ to make sure date/time work ok. Needs follow up text with confirmation details 8/28/26 JE ;; He answered and shared he is still interested just very busy with work but will call back to set up new date. 8/24/26 JE ;; MJ 08/05: Letter sent via mail No answer. Sent text. 8/4/26 JE ;; No answer. 7/29 JE ;; MJ 07/13: Pt no showed,,unresponsive to texts + calls MJ 06/22: pt had to reschedule,,moved it to 07/13 MJ 06/02: May or may not need uber | E18: 46286 | F18: 46286 | G18: 46286 | I18: TRUE
A19: 46204 | B19: DBS-0349 | C19: JE | D19: Rescheduled. Will be seen July 24th instead. 7/13/26 JE ;; Had lost his phone. Still intrested. Scheduled all visits one day. 6/25/26 JE ;; Could not leave vm, sent text + email,,response pending. MJ 06/22 ;; No answer. Sent text. 6/15/26 JE ;; No answer. No vm. WIll try again. 6/12/26 JE | E19: 46227 | F19: 46227 | G19: 46227 | I19: TRUE
A20: 46204 | B20: DBS-0430 | C20: JE | D20: No show on 7/15/26 but answered call and rescheduled JE ;; Texted back saying she has to go out of country for emergency but will be back Monday night. Rescheduling 7/9 visit to 7/15. 7/6/26 JE ;; Left message w/ sister. 6/12/26 JE | E20: 46230 | F20: 46230 | G20: 46230 | I20: TRUE
A21: 46241 | B21: DBS-0502 | C21: IV | D21: IV 8/6: traveling, reserving potential date, call 8/17 to confirm if still possible IV 7/22: left vm, sent text, followed up via text, date pending | E21: 46258 | F21: 46258 | G21: 46258 | H21: MJ 7/1: Sent | I21: TRUE
A22: 46235 | B22: DBS-0442 | C22: IV | D22: IV 9/25: rescheduled IV 8/13: rescheduled, IV 7/22: will drive | E22: 46311 | F22: 46311 | G22: 46311 | I22: TRUE
A23: 46235 | B23: DBS-0199 | C23: IV | D23: IV 7/22: will drive | E23: 46255 | F23: 46255 | G23: 46255 | I23: TRUE
A24: 46235 | B24: DBS-0429 | C24: IV | D24: IV 7/13: rescheduled Dr. H unavailableIV 7/22: will drive | E24: 46245 | F24: 46245 | G24: 46245 | I24: TRUE
A25: 46235 | B25: DBS-0381 | C25: IV | D25: IV 8/14: needs to reschedule due to dr. app, IV 7/21: needs uber, all in 1 day | E25: 46253 | F25: 46253 | G25: 46253 | H25: *have him sign front page of DE4 consent | I25: TRUE
A26: 46235 | B26: DBS-0450 | C26: JE | D26: Will need Uber. 7/9/26 JE ;; Left vm. 7/7/26 JE | E26: 46261 | F26: 46261 | G26: 46261 | I26: TRUE
A27: 46235 | B27: DBS-0586 | C27: JE | D27: All day visit. Needs uber. De4 pt. 7/7/26 JE | E27: 46234 | F27: 46234 | G27: 46234 | I27: TRUE
A28: 46235 | B28: DBS-0499 | C28: JE | D28: Wants erliest visit. 7/7/26 JE | E28: 46240 | F28: 46240 | G28: 46240 | I28: TRUE
A29: 46235 | B29: DBS-0139 | C29: MJ | D29: MJ 08/04: Sent text MJ 07/07: Call couldn't go through + sent text | E29: 46252 | F29: 46252 | G29: 46252 | I29: TRUE
A30: 46235 | B30: DBS-0404 | C30: IV | D30: MJ 08/04: Left VM +sent text MJ 07/07: Left VM + sent text | E30: 46252 | F30: 46252 | G30: 46252 | I30: TRUE
A31: 46235 | B31: DBS-0512 | C31: MJ | D31: MJ 07/07: Driving | E31: 46245 | F31: 46245 | G31: 46245 | I31: TRUE
A32: 46235 | B32: DBS-0432* | C32: MJ | D32: MJ 07/07: Left VM + sent text | E32: 46237 | F32: 46216 | G32: 46237 | I32: TRUE
A33: 46266 | B33: DBS-0676 | C33: IV | D33: IV 9/3: will drive | E33: 46294 | F33: 46294 | G33: 46294 | H33: MJ 8/4: Sent | I33: TRUE
A34: 46266 | B34: DBS-0772 | C34: IV | D34: IV 9/3: called back,needs uber left vm, sent text | E34: 46289 | F34: 46282 | G34: 46282 | I34: TRUE
A35: 46266 | B35: DBS-0830 | C35: IV | D35: IV 9/3: will drive | E35: 46300 | F35: 46300 | G35: 46300 | I35: TRUE
A36: 46296 | B36: DBS-0613 | C36: IV | D36: IV 9/16: needs uber | E36: 46296 | F36: 46296 | G36: 46296 | H36: IV 9/4: Sent | I36: TRUE
A37: 46296 | B37: DBS-0620 | C37: IV | D37: IV 9/16: left vm, sent text | I37: FALSE
A38: 46296 | B38: DBS-0055 | C38: IV | D38: IV 9/17: needs uber IV 9/16: wants a call back later | E38: 46303 | F38: 46303 | G38: 46303 | I38: TRUE
A39: 46296 | B39: DBS-0569 | C39: IV | D39: IV 9/16: will drive | E39: 46301 | F39: 46301 | G39: 46301 | I39: TRUE
A40: 46296 | B40: DBS-0745 | C40: IV | D40: IV 9/16: will drive | E40: 46321 | F40: 46321 | G40: 46321 | I40: FALSE
...

Sheet LabsMRNs
A1: DBS-ID | C1: MRN | D1: LAB DATE | E1: LABS YEAR | F1: LABS EMAILED/Texted | G1: LABS PRINTED | H1: MRI HCT | I1: notes
A2: DBS-0044 | B2: Yr 3 | C2: 004642687 | D2: 5/19/25 (MRI) 5/13/25 (Full Blood Panel) | E2: 3 | F2: 7/1 TB | G2: 6/30 NC | L2: last extract batch (to keckCap + eden HCT): 07/16/26 CTS/NC
A3: DBS-0007 | C3: 004636389 | D3: 5/22/25 (MRI) 5/19/25 (Full Blood Panel) | E3: 3 | F3: 7/1 TB | G3: 6/30 NC | L3: last extract batch: 9/2/26 NC
A4: DBS-0073 | C4: 004644039 | D4: 45807 | E4: 3 | F4: 7/1 TB | G4: 7/14 NC | H4: 45994 | I4: IV: won't find by name, search MRN for labs | L4: last batch sent to choo phei: 05/12/26 IV
A5: DBS-0169 | C5: 004644045 | D5: 45807 | E5: 3 | F5: 7/1 IV | G5: 7/14 NC | H5: 45994
A6: DBS-0053 | C6: 004638839 | D6: 45778 | E6: 3 | F6: 7/1 TB | G6: 7/14 NC
A7: DBS-0322 | C7: 004656098 | D7: 45796 | E7: 3 | F7: 7/1 TB | G7: 6/30 NC
A8: DBS-0180 | C8: 004637725 | D8: 45810 | E8: 3 | F8: 7/1 TB | G8: 7/14 NC | I8: homo missing
A9: DBS-0360 | C9: 004679104 | D9: 45813 | E9: 3 | F9: 7/1 TB | G9: 6/30 NC
A10: DBS-0054 | C10: 004650371 | D10: 6/3/25 (MRI) 6/5/25 (Full Blood Panel) | E10: 3 | F10: 7/1 TB | G10: 6/30 NC
A11: DBS-0221 | C11: 004645187 | D11: 45818 | E11: 3 | F11: 7/1 TB | G11: 6/30 NC
A12: DBS-0154 | C12: 004645753 | D12: 45819 | E12: 3 | F12: 7/1 IV | G12: 6/30 NC
A13: DBS-0008 | C13: 004650185 | D13: 45824 | E13: 3 | F13: 7/1 TB | G13: 6/30 NC
A14: DBS-0235 | C14: 004687102 | D14: 45825 | E14: 3 | F14: 7/1 TB | G14: 6/30 NC
A15: DBS-0299 | C15: 004645198 | D15: 45826 | E15: 3 | F15: 7/1 TB | G15: 6/30 NC
A16: DBS-0063 | C16: 004642697 | D16: 45833 | E16: 3 | F16: 7/1 IV | G16: 6/30 NC
A17: DBS-0430 | C17: 004706666 | D17: 45848 | E17: 3 | F17: 7/14 NC | G17: 7/14 NC
A18: DBS-0028 | C18: 004673009 | D18: 45845 | E18: 3 | F18: 8/19 IV | G18: 8/26 NC
A19: DBS-0349 | C19: 004714516 | D19: 45853 | E19: 3 | F19: 8/19 IV | G19: 8/26 NC
A20: DBS-0432 | C20: 004701973 | D20: 45875 | E20: 3 | F20: 8/19 IV | G20: 8/26 NC | H20: 45953
A21: DBS-0502 | C21: 004917321 | D21: 45876 | E21: 3 | F21: 8/19 IV | G21: 8/26 NC
A22: DBS-0499 | C22: 004909760 | D22: 45876 | E22: 3 | F22: 8/19 IV | G22: 8/26 NC
A23: DBS-0586 | C23: 004908823 | D23: 45882 | E23: 3 | F23: 8/19 IV | G23: 8/26 NC
A24: DBS-0450 | C24: 004708391 | D24: 45883 | E24: 3 | F24: 8/19 IV | G24: 8/26 NC
A25: DBS-0442 | C25: 004915910 | D25: 45884 | E25: 3 | F25: 8/19 IV | G25: 8/26 NC
A26: DBS-0199 | C26: 004707670 | D26: 45884 | E26: 3 | F26: 8/19 IV | G26: 8/26 NC
A27: DBS-0429 | C27: 004908818 | D27: 45887 | E27: 3 | F27: 8/19 IV | G27: 8/26 NC
A28: DBS-0381 | C28: 004703184 | D28: 45890 | E28: 3 | F28: 10/7 IV | G28: 10/9 CT/IV
A29: DBS-0404 | C29: 004679101 | D29: 45897 | E29: 3 | F29: 10/7 IV | G29: 10/9 CT/IV
A30: DBS-0139 | C30: 004668960 | D30: 45897 | E30: 3 | F30: 10/7 IV | G30: 10/9 CT/IV
A31: DBS-0512 | C31: 004715631 | D31: 45897 | E31: 3 | F31: 10/7 IV | G31: 10/9 CT/IV | I31: homo missing
A32: DBS-0676 | C32: 004931245 | D32: 45925 | E32: 3 | F32: 9/25 IV | G32: 10/9 CT/IV | H32: 45951
A33: DBS-0772 | C33: 004943202 | D33: 45930 | E33: 3 | F33: 10/1 IV | G33: 10/9 CT/IV | H33: 45946
A34: DBS-0613 | C34: 004924505 | D34: 45932 | E34: 3 | F34: 10/7 IV | G34: 10/9 CT/IV | H34: 45968
A35: DBS-0620 | C35: 004921829 | D35: 45933 | E35: 3 | F35: 10/7 IV | G35: 10/9 CT/IV | H35: 45980
A36: DBS-0055 | C36: 004701983 | D36: 45933 | E36: 3 | F36: 10/7 IV | G36: 10/9 CT/IV | H36: 11/7/1015
A37: DBS-0745 | C37: 004937176 | D37: 45939 | E37: 3 | F37: 10/9 IV | G37: 10/9 CT/IV | H37: 45943
A38: DBS-0498 | C38: 004921821 | D38: 46045 | E38: 3 | F38: 2/23 IV | H38: 45944
A39: DBS-0587 | C39: 004926644 | D39: 45946 | E39: 3 | F39: 11/6 AM | G39: 10/24 CT | H39: 45978
A40: DBS-0599 | C40: 004933057 | D40: 45950 | E40: 3 | F40: 11/6 AM | G40: 10/24 CT | H40: 45979
...

Sheet ClinCard
A1: Note: Baseline/2nd yr columns hidden, click + above to view | E1: Baseline | S1: Year 2 | W1: Year 3 | AD1: Year 4
A2: ID | B2: Card Number/Token # | C2: Expiration Date | E2: Date Requested | F2: Staff Requesting | G2: General Notes | H2: Participant Registered on ClinCard? (Y/N) | I2: Card Registered on ClinCard? (Y/N) | J2: Mailed or Given? Date? | K2: Screening Visit | L2: BD Credited? | M2: MRI Credited? | N2: NP Credited? | O2: LP Credited? (optional) | P2: CV Credited? | Q2: Travel Expense Mileage Rate = Roundtrip Miles * 0.70 Mileage cutoff for $50 is 38 miles (oneway) or 76 miles (roundtrip) | S2: Year 2 CV | T2: Year 2 NP | U2: Travel Expense Mileage Rate = Roundtrip Miles * 0.725 Mileage cutoff for $50 is 38 miles (oneway) or 76 miles (roundtrip) | W2: Year 3 BD | X2: Year 3 CV | Y2: Year 3 NP | Z2: Year 3 MRI | AA2: Travel Expense Mileage Rate = Roundtrip Miles * 0.725 Mileage cutoff for $50 is 38 miles (oneway) or 76 miles (roundtrip) | AB2: Notes | AD2: Year 4 BD | AE2: Year 4 CV | AF2: Year 4 NP | AG2: Travel Expense Mileage Rate = Roundtrip Miles * 0.725 Mileage cutoff for $50 is 38 miles (oneway) or 76 miles (roundtrip) | AH2: Notes
A3: DBS-0075 | B3: 5462689027584952 | C3: 45284 | E3: 44932 | F3: LC | H3: Y | I3: Y | J3: Given | K3: 25 | AJ3: Mileage Compensation Calculator
A4: DBS-0073 | B4: NEW: 15039498 14854855; 5462689024367617 | C4: 45774 | E4: 44937 | F4: LC | G4: GT 9/18: Informed $150 added to card for MRI +gas; GT 6/12: Participant informed $100 added for NP&CV | H4: Y | I4: Y | J4: Given | K4: 25 | L4: 25 | M4: 100 | N4: 50 | O4: Opt Out | P4: 50 | Q4: 50 - 4 (09/08/23) | S4: 50 | T4: 50 | U4: 50 - (06/28/24) | W4: 25 | X4: 50 | Y4: 50 | Z4: 100 | AA4: 50 (12/03/25) | AD4: 25 | AE4: 50 | AF4: 50 | AG4: 50 (5/27/26) | AJ4: Enter Miles One-way : | AK4: 14
A5: DBS-0008 | B5: NEW:45641655 NEW: 55015318 5462 6890 2414 4115: new card: 14297481 | C5: 04/27 6/24; 11/25 | E5: 44943 | F5: LC | G5: GT 5/25: Participant informed $100 included for NP & CV;LC 02/27: Participant lost her clincard. Will provide a new one in next visit scheduled for 03/21 | H5: Y | I5: Y | J5: Given | K5: 25 | L5: 25 | M5: 100 | N5: 50 | O5: 100 | P5: 50 | S5: 50 | T5: 50 | W5: 25 | X5: 50 | Y5: 50 | Z5: 100 | AA5: Uber | AB5: new card | AD5: 25 | AE5: 50 | AF5: 50 | AH5: uber/ new card | AJ5: Total Compensation: | AK5: =IF(AK4="","",ROUND(AK4*2*0.725,2)) -> 20.3
A6: DBS-0154 | B6: NEW: 95641903 5462689024430894; new card: 94302271 | C6: 10/28; 6/24; 11/25 | E6: 44946 | F6: LC | G6: GT 8/1: Informed $100 added for MRI; GT 6/6: Participant informed $100 included for NP & CV; LC 02/27: Participant lost her clincard. Will email new clinicard to home adress | H6: Y | I6: Y | J6: Given | K6: 25 | L6: 25 | M6: 100 | N6: 50 | O6: Opt Out | P6: 50 | Q6: 30.13 (06/06/23) | S6: 50 | T6: 50 | U6: 30.82 (06/17/24) | W6: 25 | X6: 50 | Y6: 50 | Z6: 100 | AA6: 30.82 (6/11/25) | AD6: 25 | AE6: 50 | AF6: 50 | AG6: 34.37 (6/29/26)
A7: DBS-0063 | B7: new card: 75046327 5462689024384497; 85028913 | C7: 6/24/2023; 04/27 | E7: 44949 | F7: LC | G7: 8/1 GT: Informed $150 added for NP & LP; 7/31 GT: Informed $147.16 added for MRI + gas | H7: Y | I7: Y | J7: Given | K7: 25 | L7: 25 | M7: 100 | N7: 50 | O7: 100 | P7: 25 | Q7: 47.16 - (07/31/23) | S7: 50 | T7: 50 | U7: $48.24 (6/06/24) | W7: 25 | X7: 50 | Y7: 50 | Z7: 100 | AA7: 50 (6/25/25) | AD7: 25 | AE7: 50 | AF7: 50 | AG7: 50 (6/10/26) | AJ7: NOT PAID
A8: DBS-0139 | B8: 55025512 64878310 | C8: 45774 | E8: 44965 | F8: GT | G8: GT 8/24: New card given, $106.68 added for MRI +gas; GT 5/8: New card given, informed active | H8: Y | I8: Y | J8: Given | K8: 25 | L8: 25 | M8: 100 | N8: 50 | O8: Opt Out | P8: 50 | Q8: 6.68 - (8/24/23) | S8: 50 | T8: 50 | U8: 6.83 (06/19/24) | W8: 25 | X8: 50 | Y8: 50 | Z8: 100 | AA8: 6.83 (8/20/25) | AD8: 25 | AE8: 50 | AF8: 50 | AG8: 7.25 (8/18/26) | AJ8: PAID
A9: DBS-0044 | B9: NEW : 74999471 5462689024244485 | C9: 45743 | E9: 44966 | F9: LC | G9: GT 6/8: Participant informed $100 included for MRI; LC 04/21: Can we re-compensate for BD since they dispatched the first one? | H9: Y | I9: Y | J9: Given | K9: 25 | L9: 25 | M9: 100 | N9: 50 | O9: Opt Out | P9: 50 | S9: 25 | T9: 50 | W9: 25 | X9: 50 | Y9: 50 | Z9: 100 | AB9: new card | AD9: 25 | AE9: 50 | AF9: 50 | AH9: UBER | AJ9: UNSURE
A10: DBS-0119 | B10: 5462 6890 2348 6988 | C10: 45101 | E10: 44970 | F10: LC | G10: LC 03/27: Participant came to initial visit but decided to no longer continue. Asked about clincard but declined compensation. | H10: N | I10: N | J10: Given | K10: 25 | AJ10: NEEDS ATTENTION
A11: DBS-0183 | B11: 5462689027601913 | C11: 45284 | E11: 44973 | F11: GT | H11: Y | I11: Y | J11: Given | K11: 25 | L11: 25 | M11: 100 | N11: 50 | O11: Opt Out | P11: 50 | S11: 25 | T11: 50
A12: DBS-0028 | B12: 94318240 | C12: 45255 | E12: 44974 | F12: GT | G12: GT 9/29: Informed $124.89 added for MRI & gas; GT 5/4: Replaced previous card | H12: Y | I12: Y | J12: Given | K12: 25 | L12: 25 | M12: 100 | N12: 50 | O12: Opt Out | P12: 50 | Q12: 24.89 (9/29/23) | S12: 50 | T12: 50 | W12: 25 | X12: 50 | Y12: 50 | Z12: 100 | AJ12: Pre-Screening (Full) | AK12: 50
A13: DBS-0131 | B13: 5462689024198988 | C13: 45101 | E13: 44987 | F13: GT | H13: Y | I13: Y | J13: Given | K13: 25 | L13: 25 | S13: 50 | T13: 50 | AJ13: Pre-Screening (Short) | AK13: 25
A14: DBS-0007 | B14: NEW Card: 35650368 64308753 | C14: 46323 | E14: 45040 | F14: GT | G14: 7/28 GT: Informed 100 for MRI; 5/12 GT informed of money from LP and NP ( Has card 84313418 in case cant find original) 4/24: Card given during CV; Card not given. Waiting for DBS clincards to come in | H14: Y | I14: Y | J14: Given | K14: 25 | L14: 25 | M14: 100 | N14: 50 | O14: 100 | P14: 25 | S14: 25 | T14: 50 | W14: 25 | X14: 50 | Y14: 50 | Z14: 100 | AD14: 25 | AE14: 50 | AF14: 50 | AH14: uber/ new card | AJ14: Baseline Medical Exam | AK14: 25
A15: DBS-0180 | B15: NEW: 75647106 NEW CARD:64996574 5462689026916569 | C15: 45284 | E15: 44992 | F15: LC | G15: GT 8/16: Informed $100 added for MRI; GT 6/22: Participant informed $75 added for CV and gas; GT 5/31: Participant informed $150 added for NP & LP | H15: Y | I15: Y | J15: Given | K15: 25 | L15: 25 | M15: 100 | N15: 50 | O15: 100 | P15: 25 | Q15: 50 - (03/07/23) | S15: 50 | T15: 50 | W15: 25 | X15: 50 | Y15: 50 | Z15: 100 | AA15: New Card:64996574/MAILED OUT ON 06/05/25 | AD15: 25 | AE15: 50 | AF15: 50 | AH15: Uber/new card | AJ15: Baseline NP | AK15: 50
A16: DBS-0053 | B16: 5462689026984930 New CARD: 95027635 NEW CARD: 35494987 | C16: 4/24/2025 05/28 | E16: 44995 | F16: LC | G16: 9/30/25 JE: Participant informed total balance $214. New card given in person. ;; 6/12 GT: Participant informed $100 added for MRI; 5/19 GT: Participant informed $75 added for NP & CV | H16: Y | I16: Y | J16: Given | K16: 25 | L16: 25 | M16: 100 | N16: 50 | O16: Opt Out | P16: 25 | S16: 25 | T16: 50 | W16: 25 | X16: 50 | Y16: 50 | Z16: 100 | AA16: NEW CARD: 35494987 | AD16: 25 | AE16: 50 | AF16: 50 | AH16: Uber | AJ16: Baseline Blood Draw | AK16: 25
A17: DBS-0212 | B17: 5462688013090693 | C17: 45255 | E17: 45001 | F17: LC | H17: Y | I17: Y | J17: Given | K17: 25 | AJ17: Baseline MRI | AK17: 100
A18: DBS-0242 | B18: 5462688013271103 | C18: 45255 | E18: 44999 | F18: GT | H18: Y | I18: Y | J18: Given | K18: 25 | AJ18: Baseline LP (Optional) | AK18: 100
A19: DBS-0128 | B19: 14317300 | C19: 45255 | E19: 45002 | F19: LC | H19: Y | I19: Y | J19: Given | K19: 25 | Q19: 50 - Lead no longer answered phone
A20: DBS-0169 | B20: NEW: 75015660 74850904; 44308551 | C20: 45774 | E20: 45005 | F20: LC | G20: GT 9/18: Informed $150 added to card for MRI +gas; GT 6/12: Participant informed $100 added for NP&CV | H20: Y | I20: Y | J20: Given | K20: 25 | L20: 25 | M20: 100 | N20: 50 | O20: Opt Out | P20: 50 | Q20: 50 - 3 (09/08/23) | S20: 50 | T20: 50 | U20: 50 - (06/28/24) | W20: 25 | X20: 50 | Y20: 50 | Z20: 100 | AA20: 50 (12/03/25) | AD20: 25 | AE20: 50 | AF20: 50 | AG20: 50 (5/27/26)
A21: DBS-0221 | B21: New card: 45016282; 94306214 | C21: 45255 | E21: 45007 | F21: GT | G21: Participant informed $100 added for LP; GT 5/31: Participant informed $125 added for NP,BD, and CV | H21: Y | I21: Y | J21: Given | K21: 25 | L21: 25 | M21: 100 | N21: 50 | O21: 100 | P21: 50 | Q21: 13.10 - (5/31/23) | S21: 50 | T21: 50 | U21: 13.4 (6/25/24) | W21: 25 | X21: 50 | Y21: 50 | Z21: 100 | AA21: 17.71 (06/11/25) | AB21: new card | AD21: 25 | AE21: 50 | AF21: 50 | AG21: 21.46 (06/23/26)
A22: DBS-0219 | B22: new card: 44852062; 14310870 | C22: 45255 | E22: 45008 | F22: LC | G22: GT 7/7: Participant informed $100 added for MRI; GT 5/10: Participant informed $75 added for NP &CV | H22: Y | I22: Y | J22: Given | K22: 25 | L22: 25 | M22: 100 | N22: 50 | O22: Opt Out | P22: 25 | S22: 50 | T22: 50 | U22: 37.52 (10/29/24) | V22: new card
A23: DBS-0061 | B23: 04292948 | C23: 45255 | E23: 45012 | F23: GT | H23: Y | I23: Y | J23: Given | K23: 25
A24: DBS-0299 | B24: NEW: 05630936 04297318 | C24: 45255 | E24: 45014 | F24: GT | G24: GT 6/9: Participant informed $125 added for NP,BD, & CV | H24: Y | I24: Y | J24: Given | K24: 25 | L24: 25 | M24: 100 | N24: 50 | O24: Opt Out | P24: 50 | Q24: 5.50 - (7/17/23) | S24: 50 | T24: 50 | U24: $6.03 (6/06/24) | W24: 50 | X24: 50 | Y24: 50 | Z24: 100 | AA24: 7.42 (6/10/25) | AD24: 25 | AE24: 50 | AF24: 50 | AG24: 7.69 (6/09/26) | AH24: New card
A25: DBS-0268 | B25: 64312498 | C25: 45255 | E25: 45015 | F25: LC | G25: GT 10/2: Informed $100 added for MRI; GT 5/10: Participant informed $50 added for NP | H25: Y | I25: Y | J25: Given | K25: 25 | L25: 25 | M25: 100 | N25: 50 | O25: Opt Out | P25: 50
A26: DBS-0054 | B26: 84306353 | C26: 45255 | E26: 45019 | F26: GT | H26: Y | I26: Y | J26: Given | K26: 25 | L26: 25 | M26: 100 | N26: 50 | O26: Opt Out | P26: 50 | S26: 50 | T26: 50 | W26: 25 | X26: 50 | Y26: 50 | Z26: 100 | AA26: Uber | AD26: 25 | AE26: 50 | AF26: 50 | AG26: Uber
A27: DBS-0322 | B27: NEW: 85654380 85037531 24287358 54863241 | C27: 46323 | E27: 45028 | F27: GT | G27: GT 7/19: Participant informed $100 added for MRI; GT 5/17: Participant informed $125 added for NP, BD, and CV | H27: Y | I27: Y | J27: Given | K27: 25 | L27: 25 | M27: 100 | N27: 50 | O27: 100 | P27: 50 | Q27: 19.65 - (4/12/23) | S27: 25 | T27: 50 | W27: 25 | X27: 50 | Y27: 50 | Z27: 100 | AB27: new card | AD27: 25 | AE27: 50 | AF27: 50 | AH27: new card
A28: DBS-0294 | B28: 64284516 | C28: 45255 | E28: 45035 | F28: GT | H28: Y | I28: Y | J28: Given | K28: 25
A29: DBS-0108 | B29: 34319219 | C29: 45255 | E29: 45037 | F29: LC | G29: GT 9/12: Participant informed $120.96 added for MRI and gas; GT 7/14: Participant informed $120.96 added for LP and gas; GT 6/23: Participant informed $141.92 added for NP,BD, & CV and gas | H29: Y | I29: Y | J29: Given | K29: 25 | L29: 25 | M29: 100 | N29: 50 | O29: 100 | P29: 25 | Q29: 20.96 (09/12/23)
A30: DBS-0010 | B30: 94305169 | C30: 45255 | E30: 45042 | F30: GT | H30: Y | I30: Y | J30: Given | K30: 25 | Q30: 3.93 - (4/26/23)
A31: DBS-0352 | B31: 34318060 | C31: 45255 | E31: 45048 | F31: LC | G31: GT 5/30: Participant informed $100 added for NP,BD, and CV; GT 5/10: Participant informed card active | H31: Y | I31: Y | J31: Given | K31: 25 | L31: 25 | M31: 100 | N31: 50 | O31: Opt Out | P31: 25 | Q31: 12.31 (10/30/23) | S31: 50 | T31: 50 | U31: 13.40 (06/03/24)
A32: DBS-0382 | B32: 34308135 | C32: 45255 | E32: 45050 | F32: LC | G32: GT 7/24: Participant informed $100 added for MRI; GT 5/19: Participant informed $100 added for NP,BD, and CV; GT 5/4: Participant informed card active | H32: Y | I32: Y | J32: Given | K32: 25 | L32: 25 | M32: 100 | N32: 50 | O32: Opt Out | P32: 25 | S32: 25 | T32: 50
A33: DBS-0013 | B33: New: 64870590 74302037 | C33: 45255 | E33: 45044 | F33: GT | G33: GT 8/8: Informed $102.62 added for MRI + gas; GT 6/14: Participant informed $125 added for NP,BD, and CV; GT 5/17: Participant informed $25 added for BD; GT 5/11 Need to send new card | H33: Y | I33: Y | J33: Given | K33: 25 | L33: 25 | M33: 100 | N33: 50 | O33: Opt Out | P33: 50 | Q33: 2.62 (8/8/23) | S33: 50 | T33: 50 | U33: 2.68 (08/12/24)
A34: DBS-0404 | B34: NEW: 75648458 74855396 | C34: 46323 | E34: 45056 | F34: GT | G34: GT 5/30: Participant informed $125 added for NP,BD, and CV; GT 5/10: Participant informed card active | H34: Y | I34: Y | J34: Given | K34: 25 | L34: 25 | M34: 100 | N34: 50 | O34: Opt Out | P34: 50 | Q34: 6.68 - (5/30/23) | S34: 50 | T34: 50 | U34: 6.83 (06/19/24) | W34: 25 | X34: 50 | Y34: 50 | Z34: 100 | AA34: 6.83 (8/28/25) | AD34: 25 | AE34: 50 | AF34: 50 | AG34: 7.25 (08/18/26) | AH34: new card
A35: DBS-0360 | B35: NEW: 95659693 74319160 | C35: 45255 | E35: 45056 | F35: GT | G35: GT 7/18: Participant informed $100 added for MRI; GT 6/1: Participant informed $150 added for NP&LP; GT 5/25: Participant informed $75 included for BD & CV; GT 5/10: Participant informed card active | H35: Y | I35: Y | J35: Given | K35: 25 | L35: 25 | M35: 100 | N35: 50 | O35: 100 | P35: 50 | S35: 50 | T35: 50 | W35: 25 | X35: 50 | Y35: 50 | Z35: 100 | AA35: 16.80 (6/5/25) | AD35: 25 | AE35: 50 | AF35: 50 | AG35: 16.80 (6/1/26)
A36: DBS-0235 | B36: 34864930; 04285594 | C36: 45255 | E36: 45069 | F36: LC | G36: GT 9/12: Informed $100 added for MRI; GT 6/19: Participant informed $100 added for BD, NP &CV; GT 5/24: Participant informed card active & $25 included for SV | H36: Y | I36: Y | J36: Given | K36: 25 | L36: 25 | M36: 100 | N36: 50 | O36: Opt Out | P36: 25 | S36: 50 | T36: 50 | W36: 25 | X36: 50 | Y36: 50 | Z36: 100 | AA36: Uber | AD36: 25 | AE36: 50 | AF36: 50 | AG36: Uber
A37: DBS-0339 | B37: 24291508 | C37: 45255 | E37: 45076 | F37: LC | G37: GT 5/30: Participant informed card active and $25 added for SV | H37: Y | I37: Y | J37: Given | K37: 25
A38: DBS-0379 | B38: NEW: 44857336 74313261 | C38: 45622 | E38: 45079 | F38: GT | G38: GT 9/21: Informed $100 added for MRI: GT 7/24: Participant informed $125 added for BD, NP &CV; GT 6/2: Participant informed $25 added for SV | H38: Y | I38: Y | J38: Given | K38: 25 | L38: 25 | M38: 100 | N38: 50 | O38: Opt Out | P38: 50 | S38: 50 | T38: 50
A39: DBS-0414 | B39: NEW: 24842638 74297611 | C39: new: 11/26 11/25 | E39: 45079 | F39: GT | G39: GT 9/21: Informed $100 added for MRI; GT 7/24: Participant informed $125 added for BD, NP &CV; GT 6/2: Participant informed $25 added for SV | H39: Y | I39: Y | J39: Given | K39: 25 | L39: 25 | M39: 100 | N39: 50 | O39: Opt Out | P39: 50 | S39: 50 | T39: 50
A40: DBS-0419 | B40: 74311938 | C40: 45255 | E40: 45079 | F40: LC | G40: GT 8/3: Participant informed $100 added for MRI; GT 6/16: Participant informed $100 added for BD, NP &CV; GT 6/2: Participant informed $25 added for SV | H40: Y | I40: Y | J40: Given | K40: 25 | L40: 25 | M40: 100 | N40: 50 | O40: Opt Out | P40: 25 | Q40: 28.82 - (06/02/23) | S40: 50 | T40: 50
...

Sheet Stool Samples
A1: ID's Eligible | B1: Status | E1: Date Given or Mailed | F1: Tracking Number if mailed | G1: Informed about Kit | H1: KIT Number | I1: Follow up notes | J1: Date Received | L1: Updated on Redcap | M1: Total Consented | N1: =SUM(N2:N6) -> 131
A2: # Complete: | B2: =COUNTIF(B3:B134,"Complete") -> 45 | M2: Completed | N2: =COUNTIF(B3:B134,"Complete") -> 45
A3: DBS-0053 | B3: Complete | C3: (i dont think they signed new consent) | D3: DBS-0715 | E3: 45210 | H3: N/A | J3: 45217 | L3: TRUE | M3: Failed to Complete | N3: =COUNTIF(B3:B134,"Failed to complete") -> 24
A4: DBS-0073 | B4: Complete | C4: (signed updated consent) | D4: DBS-1491 | E4: 45589 | F4: 1ZND00T10717112124 | G4: Y | H4: N/A | I4: 11/11 GT: Informed me he shipped it; 11/8 GT: Will try again soon, paper ripped on him so having issues collecting; 11/1 GT: Confirmed received kit, will do it soon | J4: 45609 | L4: TRUE | M4: Can still offer | N4: =COUNTIF(B3:B134,"Not offered") -> 52
A5: DBS-0169 | B5: Failed to Complete | C5: (signed updated consent) | D5: DBS-1373 | E5: 45589 | F5: 1ZND00T10716080107 | G5: Y | H5: N/A | I5: 11/1 GT: Will bring it in person day of her MRI 11/21 | L5: TRUE | M5: Declined | N5: =COUNTIF(B3:B134,"Declined") -> 2
A6: DBS-0653 | B6: Failed to Complete | D6: DBS-1492 | E6: 45589 | F6: 1ZND00T10722525106 | G6: Y | H6: N/A | I6: 11/8: Will try to send tomorrow, coming back from mammoth; 11/1 GT: Left vm | L6: TRUE | M6: Consented but dropout | N6: =COUNTIF(B3:B134,"dropout") -> 8
A7: DBS-0715 | B7: Complete | D7: DBS-1505 | E7: 45589 | F7: 1ZND00T10737439299 | G7: Y | H7: N/A | I7: 11/8 GT: Left vm, sent text; 10/31 GT: Confirmed received kit, will do it soon | L7: TRUE
A8: DBS-0745 | B8: Failed to Complete | D8: DBS-1530 | E8: 45589 | F8: 1ZND00T10718955132 | G8: Y | H8: N/A | I8: 11/8 GT: Confirmed received new kit; 11/1 GT: Didn't receive kit, sending new one to work address | K8: Send new kit 11/4 | L8: TRUE
A9: DBS-0756 | B9: Not offered | D9: DBS-1497 | E9: 45589 | F9: 1ZND00T10731141870 | G9: Y | H9: N/A | I9: 11/8 GT: Will do it by next week; 11/1 GT: Confirmed received kit, will do it soon | J9: 45611 | L9: TRUE
A10: DBS-0770 | B10: Failed to Complete | D10: DBS-1368 | E10: 45587 | F10: 1ZND00T10715920086 | G10: Y | H10: N/A | I10: 11/19 GT: Pt shipped; 11/13 GT: Called me with questions, will send kit back soon; 11/8 GT: Left vm sent text; 10/31 GT: Confirmed received kit, will do it when gets a chance | J10: 45621 | L10: TRUE
A11: DBS-0771 | B11: Complete | D11: DBS-1523 | E11: 45587 | F11: 1ZND00T10715167070 | G11: Y | H11: N/A | I11: 10/31 GT: Participant sent it back this date | J11: 45600 | L11: TRUE
A12: DBS-0789 | B12: Not offered | D12: DBS-1515 | E12: 45587 | F12: 1ZND00T10733618263 | G12: Y | H12: N/A | I12: 11/8 GT: Wasn't able to do it bc moving but will send next week; 10/31 GT: Left vm; 10/24 GT: Participant confirmed he received it | L12: TRUE
A13: DBS-0790 | B13: Not offered | D13: DBS-1521 | E13: 45587 | F13: 1ZND00T10712091095 | G13: Y | H13: N/A | I13: 11/18 UPS still has possession, waiting for delivery date; 11/14 GT: Pt sent kit back; 11/8 GT: Will do it soon; 10/31 GT: Says he will do it soon; 10/25 GT: Confirmed he received it said he'll send it back soon | J13: 45615 | L13: TRUE
A14: DBS-0798 | B14: Not offered | D14: DBS-1508 | E14: 45587 | F14: 1ZND00T10723770054 | G14: Y | H14: N/A | I14: 11/12: Pt sent kit back; 11/8 GT: Participant says he forgot will do it; 10/31 GT: Says he will do it by Monday; 10/24 GT: Participant confirmed he received it | J14: 45610 | L14: TRUE
A15: DBS-0805 | B15: Failed to Complete | D15: DBS-1315 | E15: 45772 | F15: 9405536208326289980603 | G15: Y | H15: 1 | I15: IV 6/24: sent text reminder | L15: TRUE
A16: DBS-0808 | B16: Not offered | D16: DBS-1143 | E16: 45762 | F16: 9405536208326289980689 | G16: Y | H16: 2 | J16: 45775 | L16: TRUE
A17: DBS-0818 | B17: Failed to Complete | D17: DBS-1727 | E17: 45769 | F17: 9405536208326289980740 | G17: Y | H17: 3 | J17: 45778 | L17: TRUE
A18: DBS-0822 | B18: Declined | D18: DBS-1059 | E18: 45756 | F18: 9405536208326289980818 | G18: Y | H18: 4 | J18: 45765 | L18: TRUE
A19: DBS-0824 | B19: Complete | C19: MJ 12/03: Called me to let me know that she dropped some of the liquid in the vial??Told her we will follow up if the sample is not usuable | D19: DBS-0969 | E19: 45754 | F19: 9405536208326289980863 | G19: Y | H19: 5 | I19: 4/25 GT Sent a reminder, says hasn;t been in LA but will be this weekend to do it | J19: 45776 | L19: TRUE
A20: DBS-0830 | B20: Complete | D20: DBS-1095 | E20: 45756 | F20: 9405536208326289980610 | G20: Y | H20: 6 | I20: 4/25 GT Sent reminder, will send it soon | J20: 45776 | L20: TRUE
A21: DBS-0838 | B21: Not offered | D21: DBS-1134 | E21: 45764 | F21: 9405536208326289980696 | G21: Y | H21: 7 | J21: 45771 | L21: TRUE
A22: DBS-0843 | B22: Not offered | D22: DBS-1152 | E22: 45770 | F22: 9405536208326289980771 | G22: Y | H22: 8 | J22: 45772 | L22: TRUE
A23: DBS-0876 | B23: Not offered | D23: DBS-1119 | E23: 45772 | F23: 9405536208326289980832 | G23: Y | H23: 9 | I23: IV 6/24: sent text reminder | L23: TRUE
A24: DBS-0878 | B24: Not offered | D24: DBS-1735 | E24: 45775 | F24: 9405536208326289980887 | G24: Y | H24: 10 | J24: 45779 | L24: TRUE
A25: DBS-0879 | B25: Not offered | D25: DBS-1106 | E25: 45775 | F25: 9405536208326289980634 | G25: discard, got a new one | H25: 11 | I25: IV 6/24: sent text reminder , needs new one, will stop by or ship out | L25: TRUE
A26: DBS-0884 | B26: Not offered | D26: DBS-1085 | E26: 45756 | F26: 9405536208326289980719 | G26: Y | H26: 12 | I26: IV 6/24: sent text reminder 4/25 GT sent reminder | J26: 45845 | L26: TRUE
A27: DBS-0901 | B27: Not offered | D27: DBS-1012 | E27: 45798 | F27: 9405536106193278577099 | G27: Y | H27: 13 | I27: NC 6/30: sent text reminder 6/9/25 NC sent reminder | L27: TRUE
A28: DBS-0916 | B28: Not offered | D28: DBS-0073 | E28: 45807 | F28: 9405536106193278577129 | G28: Y | H28: 14 | I28: NC 6/30 In mexico, offer in a month, left in car NC 6/30: sent text reminder 6/9/25 NC sent reminder | L28: TRUE
A29: DBS-0918 | B29: Failed to Complete | D29: DBS-0169 | E29: 45807 | F29: 9405536106193278577167 | G29: Y | H29: 15 | I29: NC 6/30 In mexico, offer in a month, left in car NC 6/30: sent text reminder 6/9/25 NC sent reminder | L29: TRUE
A30: DBS-0924 | B30: Not offered | F30: 9405536106193278577198 | H30: 16 | L30: TRUE
A31: DBS-0928 | B31: Not offered | D31: DBS-1246 | E31: 45807 | F31: 9405536106193278577211 | G31: Y | H31: 17 | I31: NC 6/30: sent text reminder 6/9/25 NC sent reminder | L31: TRUE
A32: DBS-0935 | B32: Not offered | D32: DBS-1106 | E32: 45834 | F32: 9405536106193278577105 | G32: Y | H32: 18 | I32: IV 6/26: picked up new kit IV 6/24: sent text reminder , needs new one, will stop by or ship out | J32: 45835 | L32: TRUE
A33: DBS-0940 | B33: Failed to Complete | D33: DBS-1047 | E33: 45840 | F33: 9405536106193278577136 | G33: Y | H33: 19 | I33: NC 7/30 sent reminder AG 7/23 sent follow up text | L33: TRUE
A34: DBS-0956 | B34: Complete | D34: DBS-1008 | E34: 45840 | F34: 9405536106193278577150 | G34: Y | H34: 20 | I34: NC 7/30 sent reminder AG 7/23 sent follow up text | L34: TRUE
A35: DBS-0969 | B35: Complete | D35: DBS-1156 | E35: 45852 | F35: 9405536106193278577181 | G35: Y | H35: 21 | I35: NC 7/30 sent reminder AG 7/23 sent follow up text | J35: 45873 | L35: TRUE
A36: DBS-0971 | B36: Complete | D36: DBS-1063 | E36: 45908 | F36: 9405536106193278577204 | G36: Y | H36: 22 | I36: IV 9/23: received | J36: 45923 | L36: TRUE
A37: DBS-0981 | B37: Not offered | D37: DBS:1167 Checked in through text. Pending response 5/5/26 JE ;; Reminder text sent NC 9/2 | E37: 45880 | F37: 9405536106193278577112 | G37: Y | H37: 23 | I37: Reminder text sent NC 9/2 | L37: TRUE
A38: DBS-0982 | B38: Complete | D38: DBS-1392 | E38: 45896 | F38: 9405536106193278577143 | G38: Y | H38: 24 | I38: Reminder text send NC 9/9 (responded that she sent it that day) | J38: 45910 | L38: TRUE
A39: DBS-0987 | B39: Complete | F39: 9405536106193283632813 | H39: 25 | L39: TRUE
A40: DBS-1000 | B40: Complete | D40: DBS-1480 | E40: 45923 | F40: 9405536106193283632851 | G40: Y | H40: 26 | J40: 45931 | L40: TRUE
...

Sheet Study Partner
